2025-09-17 21:05:23,122 [INFO] worker: ENGINE selected: patchright
2025-09-17 21:05:23,215 [ERROR] worker: resolve_timezone_via_proxy failed
Traceback (most recent call last):
  File "D:\SOFTS\AntiServer\worker.py", line 155, in run_worker
    tz = await resolve_timezone_via_proxy(server, creds)
         ^^^^^^^^^^^^^^^^^^^^^^^^^^^^^^^^^^^^^^^^^^^^^^^
  File "D:\SOFTS\AntiServer\utils.py", line 62, in resolve_timezone_via_proxy
    async with httpx.AsyncClient(proxies=proxy_url, timeout=timeout, verify=False) as client:
               ^^^^^^^^^^^^^^^^^^^^^^^^^^^^^^^^^^^^^^^^^^^^^^^^^^^^^^^^^^^^^^^^^^^
TypeError: AsyncClient.__init__() got an unexpected keyword argument 'proxies'
2025-09-17 21:05:26,111 [ERROR] worker: Failed to refresh tz init script dynamically
Traceback (most recent call last):
  File "C:\Users\rubes\AppData\Local\Programs\Python\Python312\Lib\zoneinfo\_common.py", line 12, in load_tzdata
    return resources.files(package_name).joinpath(resource_name).open("rb")
           ^^^^^^^^^^^^^^^^^^^^^^^^^^^^^
  File "C:\Users\rubes\AppData\Local\Programs\Python\Python312\Lib\importlib\resources\_common.py", line 46, in wrapper
    return func(anchor)
           ^^^^^^^^^^^^
  File "C:\Users\rubes\AppData\Local\Programs\Python\Python312\Lib\importlib\resources\_common.py", line 56, in files
    return from_package(resolve(anchor))
                        ^^^^^^^^^^^^^^^
  File "C:\Users\rubes\AppData\Local\Programs\Python\Python312\Lib\functools.py", line 909, in wrapper
    return dispatch(args[0].__class__)(*args, **kw)
           ^^^^^^^^^^^^^^^^^^^^^^^^^^^^^^^^^^^^^^^^
  File "C:\Users\rubes\AppData\Local\Programs\Python\Python312\Lib\importlib\resources\_common.py", line 82, in _
    return importlib.import_module(cand)
           ^^^^^^^^^^^^^^^^^^^^^^^^^^^^^
  File "C:\Users\rubes\AppData\Local\Programs\Python\Python312\Lib\importlib\__init__.py", line 90, in import_module
    return _bootstrap._gcd_import(name[level:], package, level)
           ^^^^^^^^^^^^^^^^^^^^^^^^^^^^^^^^^^^^^^^^^^^^^^^^^^^^
  File "<frozen importlib._bootstrap>", line 1381, in _gcd_import
  File "<frozen importlib._bootstrap>", line 1354, in _find_and_load
  File "<frozen importlib._bootstrap>", line 1304, in _find_and_load_unlocked
  File "<frozen importlib._bootstrap>", line 488, in _call_with_frames_removed
  File "<frozen importlib._bootstrap>", line 1381, in _gcd_import
  File "<frozen importlib._bootstrap>", line 1354, in _find_and_load
  File "<frozen importlib._bootstrap>", line 1304, in _find_and_load_unlocked
  File "<frozen importlib._bootstrap>", line 488, in _call_with_frames_removed
  File "<frozen importlib._bootstrap>", line 1381, in _gcd_import
  File "<frozen importlib._bootstrap>", line 1354, in _find_and_load
  File "<frozen importlib._bootstrap>", line 1318, in _find_and_load_unlocked
ModuleNotFoundError: No module named 'tzdata'

During handling of the above exception, another exception occurred:

Traceback (most recent call last):
  File "D:\SOFTS\AntiServer\worker.py", line 111, in _realign_tz_from_inside
    now = datetime.now(ZoneInfo(tz))
                       ^^^^^^^^^^^^
  File "C:\Users\rubes\AppData\Local\Programs\Python\Python312\Lib\zoneinfo\_common.py", line 24, in load_tzdata
    raise ZoneInfoNotFoundError(f"No time zone found with key {key}")
zoneinfo._common.ZoneInfoNotFoundError: 'No time zone found with key Europe/Warsaw'
2025-09-17 21:05:26,126 [INFO] worker: Re-aligned timezone from inside browser to: Europe/Warsaw
