Traceback (most recent call last):
  File "D:\SOFTS\AntiServer\worker.py", line 12, in <module>
    from patchright.async_api import async_playwright
ModuleNotFoundError: No module named 'patchright'
Traceback (most recent call last):
  File "D:\SOFTS\AntiServer\worker.py", line 12, in <module>
    from patchright.async_api import async_playwright
ModuleNotFoundError: No module named 'patchright'
Traceback (most recent call last):
  File "D:\SOFTS\AntiServer\worker.py", line 12, in <module>
    from patchright.async_api import async_playwright
ModuleNotFoundError: No module named 'patchright'
Exception ignored in: <coroutine object run_worker at 0x000002488438A7A0>
Traceback (most recent call last):
  File "D:\SOFTS\AntiServer\worker.py", line 42, in run_worker
    async with async_playwright() as p:
  File "D:\SOFTS\AntiServer\.venv\Lib\site-packages\playwright\async_api\_context_manager.py", line 57, in __aexit__
    await self._connection.stop_async()
  File "D:\SOFTS\AntiServer\.venv\Lib\site-packages\playwright\_impl\_connection.py", line 283, in stop_async
    self._transport.request_stop()
  File "D:\SOFTS\AntiServer\.venv\Lib\site-packages\playwright\_impl\_transport.py", line 99, in request_stop
    self._output.close()
  File "C:\Users\rubes\AppData\Local\Programs\Python\Python312\Lib\asyncio\streams.py", line 343, in close
    return self._transport.close()
           ^^^^^^^^^^^^^^^^^^^^^^^
  File "C:\Users\rubes\AppData\Local\Programs\Python\Python312\Lib\asyncio\proactor_events.py", line 109, in close
    self._loop.call_soon(self._call_connection_lost, None)
  File "C:\Users\rubes\AppData\Local\Programs\Python\Python312\Lib\asyncio\base_events.py", line 772, in call_soon
    self._check_closed()
  File "C:\Users\rubes\AppData\Local\Programs\Python\Python312\Lib\asyncio\base_events.py", line 519, in _check_closed
    raise RuntimeError('Event loop is closed')
RuntimeError: Event loop is closed
Task was destroyed but it is pending!
task: <Task cancelling name='Task-5' coro=<run_worker.<locals>.heartbeat() running at D:\SOFTS\AntiServer\worker.py:75> wait_for=<Future cancelled>>
Exception ignored in: <function _ProactorBasePipeTransport.__del__ at 0x00000248840E6700>
Traceback (most recent call last):
  File "C:\Users\rubes\AppData\Local\Programs\Python\Python312\Lib\asyncio\proactor_events.py", line 116, in __del__
    _warn(f"unclosed transport {self!r}", ResourceWarning, source=self)
                               ^^^^^^^^
  File "C:\Users\rubes\AppData\Local\Programs\Python\Python312\Lib\asyncio\proactor_events.py", line 80, in __repr__
    info.append(f'fd={self._sock.fileno()}')
                      ^^^^^^^^^^^^^^^^^^^
  File "C:\Users\rubes\AppData\Local\Programs\Python\Python312\Lib\asyncio\windows_utils.py", line 102, in fileno
    raise ValueError("I/O operation on closed pipe")
ValueError: I/O operation on closed pipe
Exception ignored in: <function BaseSubprocessTransport.__del__ at 0x00000248840E4E00>
Traceback (most recent call last):
  File "C:\Users\rubes\AppData\Local\Programs\Python\Python312\Lib\asyncio\base_subprocess.py", line 125, in __del__
    _warn(f"unclosed transport {self!r}", ResourceWarning, source=self)
                               ^^^^^^^^
  File "C:\Users\rubes\AppData\Local\Programs\Python\Python312\Lib\asyncio\base_subprocess.py", line 70, in __repr__
    info.append(f'stdin={stdin.pipe}')
                        ^^^^^^^^^^^^
  File "C:\Users\rubes\AppData\Local\Programs\Python\Python312\Lib\asyncio\proactor_events.py", line 80, in __repr__
    info.append(f'fd={self._sock.fileno()}')
                      ^^^^^^^^^^^^^^^^^^^
  File "C:\Users\rubes\AppData\Local\Programs\Python\Python312\Lib\asyncio\windows_utils.py", line 102, in fileno
    raise ValueError("I/O operation on closed pipe")
ValueError: I/O operation on closed pipe
Task was destroyed but it is pending!
task: <Task pending name='Task-2' coro=<Connection.run() running at D:\SOFTS\AntiServer\.venv\Lib\site-packages\playwright\_impl\_connection.py:274> wait_for=<Future pending cb=[Task.task_wakeup()]>>
